sqlalchemy.exc.OperationalError
sqlalchemy.exc.OperationalError: (sqlite3.OperationalError) table user has no column named phone
[SQL: INSERT INTO user (email, password, name, phone) VALUES (?, ?, ?, ?)]
[parameters: ('Danu1234@gmail.com', 'pbkdf2:sha256:1000000$hKMSezf5n4v5i0yU$57d97efedfd807d782b9490497dce392832a0414842f48ba7ac767793e1e9954', 'Susa', '0714123478')]
(Background on this error at: https://sqlalche.me/e/20/e3q8)

Traceback (most recent call last)
File "/home/runner/workspace/.pythonlibs/lib/python3.13/site-packages/sqlalchemy/engine/base.py", line 1963, in _exec_single_context
self.dialect.do_execute(
^
File "/home/runner/workspace/.pythonlibs/lib/python3.13/site-packages/sqlalchemy/engine/default.py", line 943, in do_execute
cursor.execute(statement, parameters)
^^^^^^^^^^^^^^^^^^^^^^^^^^^^^^^^^^^^^
The above exception was the direct cause of the following exception:
File "/home/runner/workspace/.pythonlibs/lib/python3.13/site-packages/flask/app.py", line 1536, in __call__
return self.wsgi_app(environ, start_response)
       ^^^^^^^^^^^^^^^^^^^^^^^^^^^^^^^^^^^^^^
File "/home/runner/workspace/.pythonlibs/lib/python3.13/site-packages/flask/app.py", line 1514, in wsgi_app
response = self.handle_exception(e)
           ^^^^^^^^^^^^^^^^^^^^^^^^
File "/home/runner/workspace/.pythonlibs/lib/python3.13/site-packages/flask/app.py", line 1511, in wsgi_app
response = self.full_dispatch_request()
           ^^^^^^^^^^^^^^^^^^^^^^^^^^^^
File "/home/runner/workspace/.pythonlibs/lib/python3.13/site-packages/flask/app.py", line 919, in full_dispatch_request
rv = self.handle_user_exception(e)
     ^^^^^^^^^^^^^^^^^^^^^^^^^^^^^
File "/home/runner/workspace/.pythonlibs/lib/python3.13/site-packages/flask/app.py", line 917, in full_dispatch_request
rv = self.dispatch_request()
     ^^^^^^^^^^^^^^^^^^^^^^^
File "/home/runner/workspace/.pythonlibs/lib/python3.13/site-packages/flask/app.py", line 902, in dispatch_request
return self.ensure_sync(self.view_functions[rule.endpoint])(**view_args)  # type: ignore[no-any-return]
       ^^^^^^^^^^^^^^^^^^^^^^^^^^^^^^^^^^^^^^^^^^^^^^^^^^^^^^^^^^^^^^^^^
File "/home/runner/workspace/auth.py", line 36, in register
db.session.commit()
^^^^^^^^^^^^^^^^^^^
File "/home/runner/workspace/.pythonlibs/lib/python3.13/site-packages/sqlalchemy/orm/scoping.py", line 599, in commit
return self._proxied.commit()
       ^^^^^^^^^^^^^^^^^^^^^^
File "/home/runner/workspace/.pythonlibs/lib/python3.13/site-packages/sqlalchemy/orm/session.py", line 2032, in commit
trans.commit(_to_root=True)
^^^^^^^^^^^^^^^^^^^^^^^^^^^
File "<string>", line 2, in commit
File "/home/runner/workspace/.pythonlibs/lib/python3.13/site-packages/sqlalchemy/orm/state_changes.py", line 139, in _go
ret_value = fn(self, *arg, **kw)
            ^^^^^^^^^^^^^^^^^^^^
File "/home/runner/workspace/.pythonlibs/lib/python3.13/site-packages/sqlalchemy/orm/session.py", line 1313, in commit
self._prepare_impl()
^^^^^^^^^^^^^^^^^^^^
File "<string>", line 2, in _prepare_impl
File "/home/runner/workspace/.pythonlibs/lib/python3.13/site-packages/sqlalchemy/orm/state_changes.py", line 139, in _go
ret_value = fn(self, *arg, **kw)
            ^^^^^^^^^^^^^^^^^^^^
File "/home/runner/workspace/.pythonlibs/lib/python3.13/site-packages/sqlalchemy/orm/session.py", line 1288, in _prepare_impl
self.session.flush()
^^^^^^^^^^^^^^^^^^^^
File "/home/runner/workspace/.pythonlibs/lib/python3.13/site-packages/sqlalchemy/orm/session.py", line 4345, in flush
self._flush(objects)
^^^^^^^^^^^^^^^^^^^^
File "/home/runner/workspace/.pythonlibs/lib/python3.13/site-packages/sqlalchemy/orm/session.py", line 4480, in _flush
with util.safe_reraise():
     ^^^^^^^^^^^^^^^^^^^
File "/home/runner/workspace/.pythonlibs/lib/python3.13/site-packages/sqlalchemy/util/langhelpers.py", line 224, in __exit__
raise exc_value.with_traceback(exc_tb)
^^^^^^^^^^^^^^^^^^^^^^^^^^^^^^^^^^^^^^
File "/home/runner/workspace/.pythonlibs/lib/python3.13/site-packages/sqlalchemy/orm/session.py", line 4441, in _flush
flush_context.execute()
^^^^^^^^^^^^^^^^^^^^^^^
File "/home/runner/workspace/.pythonlibs/lib/python3.13/site-packages/sqlalchemy/orm/unitofwork.py", line 466, in execute
rec.execute(self)
^^^^^^^^^^^^^^^^^
File "/home/runner/workspace/.pythonlibs/lib/python3.13/site-packages/sqlalchemy/orm/unitofwork.py", line 642, in execute
util.preloaded.orm_persistence.save_obj(
^
File "/home/runner/workspace/.pythonlibs/lib/python3.13/site-packages/sqlalchemy/orm/persistence.py", line 93, in save_obj
_emit_insert_statements(
^
File "/home/runner/workspace/.pythonlibs/lib/python3.13/site-packages/sqlalchemy/orm/persistence.py", line 1233, in _emit_insert_statements
result = connection.execute(
         
File "/home/runner/workspace/.pythonlibs/lib/python3.13/site-packages/sqlalchemy/engine/base.py", line 1415, in execute
return meth(
       
File "/home/runner/workspace/.pythonlibs/lib/python3.13/site-packages/sqlalchemy/sql/elements.py", line 523, in _execute_on_connection
return connection._execute_clauseelement(
       
File "/home/runner/workspace/.pythonlibs/lib/python3.13/site-packages/sqlalchemy/engine/base.py", line 1637, in _execute_clauseelement
ret = self._execute_context(
      
File "/home/runner/workspace/.pythonlibs/lib/python3.13/site-packages/sqlalchemy/engine/base.py", line 1842, in _execute_context
return self._exec_single_context(
       
File "/home/runner/workspace/.pythonlibs/lib/python3.13/site-packages/sqlalchemy/engine/base.py", line 1982, in _exec_single_context
self._handle_dbapi_exception(
^
File "/home/runner/workspace/.pythonlibs/lib/python3.13/site-packages/sqlalchemy/engine/base.py", line 2351, in _handle_dbapi_exception
raise sqlalchemy_exception.with_traceback(exc_info[2]) from e
^^^^^^^^^^^^^^^^^^^^^^^^^^^^^^^^^^^^^^^^^^^^^^^^^^^^^^^^^^^^^
File "/home/runner/workspace/.pythonlibs/lib/python3.13/site-packages/sqlalchemy/engine/base.py", line 1963, in _exec_single_context
self.dialect.do_execute(
^
File "/home/runner/workspace/.pythonlibs/lib/python3.13/site-packages/sqlalchemy/engine/default.py", line 943, in do_execute
cursor.execute(statement, parameters)
^^^^^^^^^^^^^^^^^^^^^^^^^^^^^^^^^^^^^
sqlalchemy.exc.OperationalError: (sqlite3.OperationalError) table user has no column named phone
[SQL: INSERT INTO user (email, password, name, phone) VALUES (?, ?, ?, ?)]
[parameters: ('Danu1234@gmail.com', 'pbkdf2:sha256:1000000$hKMSezf5n4v5i0yU$57d97efedfd807d782b9490497dce392832a0414842f48ba7ac767793e1e9954', 'Susa', '0714123478')]
(Background on this error at: https://sqlalche.me/e/20/e3q8)
The debugger caught an exception in your WSGI application. You can now look at the traceback which led to the error.
To switch between the interactive traceback and the plaintext one, you can click on the "Traceback" headline. From the text traceback you can also create a paste of it.

